[2025-02-05T13:27:06.296+0000] {local_task_job_runner.py:123} INFO - ::group::Pre task execution logs
[2025-02-05T13:27:06.476+0000] {taskinstance.py:2613} INFO - Dependencies all met for dep_context=non-requeueable deps ti=<TaskInstance: etl_dag_incremental.get_last_timestamp scheduled__2024-01-01T00:01:00+00:00 [queued]>
[2025-02-05T13:27:06.485+0000] {taskinstance.py:2613} INFO - Dependencies all met for dep_context=requeueable deps ti=<TaskInstance: etl_dag_incremental.get_last_timestamp scheduled__2024-01-01T00:01:00+00:00 [queued]>
[2025-02-05T13:27:06.486+0000] {taskinstance.py:2866} INFO - Starting attempt 2 of 2
[2025-02-05T13:27:06.499+0000] {taskinstance.py:2889} INFO - Executing <Task(PythonOperator): get_last_timestamp> on 2024-01-01 00:01:00+00:00
[2025-02-05T13:27:06.509+0000] {warnings.py:112} WARNING - /home/***/.local/lib/python3.12/site-packages/***/task/task_runner/standard_task_runner.py:70: DeprecationWarning: This process (pid=367) is multi-threaded, use of fork() may lead to deadlocks in the child.
  pid = os.fork()

[2025-02-05T13:27:06.510+0000] {standard_task_runner.py:72} INFO - Started process 369 to run task
[2025-02-05T13:27:06.511+0000] {standard_task_runner.py:104} INFO - Running: ['***', 'tasks', 'run', 'etl_dag_incremental', 'get_last_timestamp', 'scheduled__2024-01-01T00:01:00+00:00', '--job-id', '12', '--raw', '--subdir', 'DAGS_FOLDER/etl.py', '--cfg-path', '/tmp/tmp_rk57f2q']
[2025-02-05T13:27:06.512+0000] {standard_task_runner.py:105} INFO - Job 12: Subtask get_last_timestamp
[2025-02-05T13:27:06.547+0000] {task_command.py:467} INFO - Running <TaskInstance: etl_dag_incremental.get_last_timestamp scheduled__2024-01-01T00:01:00+00:00 [running]> on host cc4d22238cdc
[2025-02-05T13:27:06.616+0000] {taskinstance.py:3132} INFO - Exporting env vars: AIRFLOW_CTX_DAG_OWNER='***' AIRFLOW_CTX_DAG_ID='etl_dag_incremental' AIRFLOW_CTX_TASK_ID='get_last_timestamp' AIRFLOW_CTX_EXECUTION_DATE='2024-01-01T00:01:00+00:00' AIRFLOW_CTX_TRY_NUMBER='2' AIRFLOW_CTX_DAG_RUN_ID='scheduled__2024-01-01T00:01:00+00:00'
[2025-02-05T13:27:06.617+0000] {logging_mixin.py:190} INFO - Task instance is in running state
[2025-02-05T13:27:06.617+0000] {logging_mixin.py:190} INFO -  Previous state of the Task instance: queued
[2025-02-05T13:27:06.617+0000] {logging_mixin.py:190} INFO - Current task name:get_last_timestamp state:running start_date:2025-02-05 13:27:06.477123+00:00
[2025-02-05T13:27:06.618+0000] {logging_mixin.py:190} INFO - Dag name:etl_dag_incremental and current dag run status:running
[2025-02-05T13:27:06.618+0000] {taskinstance.py:731} INFO - ::endgroup::
[2025-02-05T13:27:06.618+0000] {taskinstance.py:3311} ERROR - Task failed with exception
Traceback (most recent call last):
  File "/home/airflow/.local/lib/python3.12/site-packages/airflow/models/taskinstance.py", line 767, in _execute_task
    result = _execute_callable(context=context, **execute_callable_kwargs)
             ^^^^^^^^^^^^^^^^^^^^^^^^^^^^^^^^^^^^^^^^^^^^^^^^^^^^^^^^^^^^^
  File "/home/airflow/.local/lib/python3.12/site-packages/airflow/models/taskinstance.py", line 733, in _execute_callable
    return ExecutionCallableRunner(
           ^^^^^^^^^^^^^^^^^^^^^^^^
  File "/home/airflow/.local/lib/python3.12/site-packages/airflow/utils/operator_helpers.py", line 252, in run
    return self.func(*args, **kwargs)
           ^^^^^^^^^^^^^^^^^^^^^^^^^^
  File "/home/airflow/.local/lib/python3.12/site-packages/airflow/models/baseoperator.py", line 422, in wrapper
    return func(self, *args, **kwargs)
           ^^^^^^^^^^^^^^^^^^^^^^^^^^^
  File "/home/airflow/.local/lib/python3.12/site-packages/airflow/operators/python.py", line 238, in execute
    return_value = self.execute_callable()
                   ^^^^^^^^^^^^^^^^^^^^^^^
  File "/home/airflow/.local/lib/python3.12/site-packages/airflow/operators/python.py", line 256, in execute_callable
    return runner.run(*self.op_args, **self.op_kwargs)
           ^^^^^^^^^^^^^^^^^^^^^^^^^^^^^^^^^^^^^^^^^^^
  File "/home/airflow/.local/lib/python3.12/site-packages/airflow/utils/operator_helpers.py", line 252, in run
    return self.func(*args, **kwargs)
           ^^^^^^^^^^^^^^^^^^^^^^^^^^
  File "/opt/airflow/dags/etl.py", line 35, in get_last_timestamp
    last_timestamp = ti.xcom_pull(task_ids='save_last_timestamp', default_var="2000-01-01 00:00:00")
                     ^^^^^^^^^^^^^^^^^^^^^^^^^^^^^^^^^^^^^^^^^^^^^^^^^^^^^^^^^^^^^^^^^^^^^^^^^^^^^^^
  File "/home/airflow/.local/lib/python3.12/site-packages/airflow/utils/session.py", line 97, in wrapper
    return func(*args, session=session, **kwargs)
           ^^^^^^^^^^^^^^^^^^^^^^^^^^^^^^^^^^^^^^
TypeError: TaskInstance.xcom_pull() got an unexpected keyword argument 'default_var'
[2025-02-05T13:27:06.626+0000] {logging_mixin.py:190} INFO - Task instance in failure state
[2025-02-05T13:27:06.626+0000] {logging_mixin.py:190} INFO - Task start:2025-02-05 13:27:06.477123+00:00 end:2025-02-05 13:27:06.626160+00:00 duration:0.149037
[2025-02-05T13:27:06.627+0000] {logging_mixin.py:190} INFO - Task:<Task(PythonOperator): get_last_timestamp> dag:<DAG: etl_dag_incremental> dagrun:<DagRun etl_dag_incremental @ 2024-01-01 00:01:00+00:00: scheduled__2024-01-01T00:01:00+00:00, state:running, queued_at: 2025-02-05 13:22:02.493711+00:00. externally triggered: False>
[2025-02-05T13:27:06.627+0000] {logging_mixin.py:190} INFO - Failure caused by TaskInstance.xcom_pull() got an unexpected keyword argument 'default_var'
[2025-02-05T13:27:06.627+0000] {taskinstance.py:1225} INFO - Marking task as FAILED. dag_id=etl_dag_incremental, task_id=get_last_timestamp, run_id=scheduled__2024-01-01T00:01:00+00:00, execution_date=20240101T000100, start_date=20250205T132706, end_date=20250205T132706
[2025-02-05T13:27:06.636+0000] {taskinstance.py:340} INFO - ::group::Post task execution logs
[2025-02-05T13:27:06.636+0000] {standard_task_runner.py:124} ERROR - Failed to execute job 12 for task get_last_timestamp (TaskInstance.xcom_pull() got an unexpected keyword argument 'default_var'; 369)
Traceback (most recent call last):
  File "/home/airflow/.local/lib/python3.12/site-packages/airflow/task/task_runner/standard_task_runner.py", line 117, in _start_by_fork
    ret = args.func(args, dag=self.dag)
          ^^^^^^^^^^^^^^^^^^^^^^^^^^^^^
  File "/home/airflow/.local/lib/python3.12/site-packages/airflow/cli/cli_config.py", line 49, in command
    return func(*args, **kwargs)
           ^^^^^^^^^^^^^^^^^^^^^
  File "/home/airflow/.local/lib/python3.12/site-packages/airflow/utils/cli.py", line 116, in wrapper
    return f(*args, **kwargs)
           ^^^^^^^^^^^^^^^^^^
  File "/home/airflow/.local/lib/python3.12/site-packages/airflow/cli/commands/task_command.py", line 483, in task_run
    task_return_code = _run_task_by_selected_method(args, _dag, ti)
                       ^^^^^^^^^^^^^^^^^^^^^^^^^^^^^^^^^^^^^^^^^^^^
  File "/home/airflow/.local/lib/python3.12/site-packages/airflow/cli/commands/task_command.py", line 256, in _run_task_by_selected_method
    return _run_raw_task(args, ti)
           ^^^^^^^^^^^^^^^^^^^^^^^
  File "/home/airflow/.local/lib/python3.12/site-packages/airflow/cli/commands/task_command.py", line 341, in _run_raw_task
    return ti._run_raw_task(
           ^^^^^^^^^^^^^^^^^
  File "/home/airflow/.local/lib/python3.12/site-packages/airflow/utils/session.py", line 97, in wrapper
    return func(*args, session=session, **kwargs)
           ^^^^^^^^^^^^^^^^^^^^^^^^^^^^^^^^^^^^^^
  File "/home/airflow/.local/lib/python3.12/site-packages/airflow/models/taskinstance.py", line 3005, in _run_raw_task
    return _run_raw_task(
           ^^^^^^^^^^^^^^
  File "/home/airflow/.local/lib/python3.12/site-packages/airflow/models/taskinstance.py", line 273, in _run_raw_task
    TaskInstance._execute_task_with_callbacks(
  File "/home/airflow/.local/lib/python3.12/site-packages/airflow/models/taskinstance.py", line 3159, in _execute_task_with_callbacks
    result = self._execute_task(context, task_orig)
             ^^^^^^^^^^^^^^^^^^^^^^^^^^^^^^^^^^^^^^
  File "/home/airflow/.local/lib/python3.12/site-packages/airflow/models/taskinstance.py", line 3183, in _execute_task
    return _execute_task(self, context, task_orig)
           ^^^^^^^^^^^^^^^^^^^^^^^^^^^^^^^^^^^^^^^
  File "/home/airflow/.local/lib/python3.12/site-packages/airflow/models/taskinstance.py", line 767, in _execute_task
    result = _execute_callable(context=context, **execute_callable_kwargs)
             ^^^^^^^^^^^^^^^^^^^^^^^^^^^^^^^^^^^^^^^^^^^^^^^^^^^^^^^^^^^^^
  File "/home/airflow/.local/lib/python3.12/site-packages/airflow/models/taskinstance.py", line 733, in _execute_callable
    return ExecutionCallableRunner(
           ^^^^^^^^^^^^^^^^^^^^^^^^
  File "/home/airflow/.local/lib/python3.12/site-packages/airflow/utils/operator_helpers.py", line 252, in run
    return self.func(*args, **kwargs)
           ^^^^^^^^^^^^^^^^^^^^^^^^^^
  File "/home/airflow/.local/lib/python3.12/site-packages/airflow/models/baseoperator.py", line 422, in wrapper
    return func(self, *args, **kwargs)
           ^^^^^^^^^^^^^^^^^^^^^^^^^^^
  File "/home/airflow/.local/lib/python3.12/site-packages/airflow/operators/python.py", line 238, in execute
    return_value = self.execute_callable()
                   ^^^^^^^^^^^^^^^^^^^^^^^
  File "/home/airflow/.local/lib/python3.12/site-packages/airflow/operators/python.py", line 256, in execute_callable
    return runner.run(*self.op_args, **self.op_kwargs)
           ^^^^^^^^^^^^^^^^^^^^^^^^^^^^^^^^^^^^^^^^^^^
  File "/home/airflow/.local/lib/python3.12/site-packages/airflow/utils/operator_helpers.py", line 252, in run
    return self.func(*args, **kwargs)
           ^^^^^^^^^^^^^^^^^^^^^^^^^^
  File "/opt/airflow/dags/etl.py", line 35, in get_last_timestamp
    last_timestamp = ti.xcom_pull(task_ids='save_last_timestamp', default_var="2000-01-01 00:00:00")
                     ^^^^^^^^^^^^^^^^^^^^^^^^^^^^^^^^^^^^^^^^^^^^^^^^^^^^^^^^^^^^^^^^^^^^^^^^^^^^^^^
  File "/home/airflow/.local/lib/python3.12/site-packages/airflow/utils/session.py", line 97, in wrapper
    return func(*args, session=session, **kwargs)
           ^^^^^^^^^^^^^^^^^^^^^^^^^^^^^^^^^^^^^^
TypeError: TaskInstance.xcom_pull() got an unexpected keyword argument 'default_var'
[2025-02-05T13:27:06.684+0000] {local_task_job_runner.py:266} INFO - Task exited with return code 1
[2025-02-05T13:27:06.711+0000] {taskinstance.py:3895} INFO - 0 downstream tasks scheduled from follow-on schedule check
[2025-02-05T13:27:06.715+0000] {local_task_job_runner.py:245} INFO - ::endgroup::
