[2025-02-06T14:16:02.617+0000] {local_task_job_runner.py:123} INFO - ::group::Pre task execution logs
[2025-02-06T14:16:02.643+0000] {taskinstance.py:2613} INFO - Dependencies all met for dep_context=non-requeueable deps ti=<TaskInstance: etl_dag_incremental.extract_online_store_data manual__2025-02-06T14:10:35.575774+00:00 [queued]>
[2025-02-06T14:16:02.654+0000] {taskinstance.py:2613} INFO - Dependencies all met for dep_context=requeueable deps ti=<TaskInstance: etl_dag_incremental.extract_online_store_data manual__2025-02-06T14:10:35.575774+00:00 [queued]>
[2025-02-06T14:16:02.655+0000] {taskinstance.py:2866} INFO - Starting attempt 1 of 2
[2025-02-06T14:16:02.674+0000] {taskinstance.py:2889} INFO - Executing <Task(PythonOperator): extract_online_store_data> on 2025-02-06 14:10:35.575774+00:00
[2025-02-06T14:16:02.686+0000] {warnings.py:112} WARNING - /home/***/.local/lib/python3.12/site-packages/***/task/task_runner/standard_task_runner.py:70: DeprecationWarning: This process (pid=171) is multi-threaded, use of fork() may lead to deadlocks in the child.
  pid = os.fork()

[2025-02-06T14:16:02.688+0000] {standard_task_runner.py:72} INFO - Started process 175 to run task
[2025-02-06T14:16:02.688+0000] {standard_task_runner.py:104} INFO - Running: ['***', 'tasks', 'run', 'etl_dag_incremental', 'extract_online_store_data', 'manual__2025-02-06T14:10:35.575774+00:00', '--job-id', '250', '--raw', '--subdir', 'DAGS_FOLDER/etl.py', '--cfg-path', '/tmp/tmpeoh9jmp4']
[2025-02-06T14:16:02.690+0000] {standard_task_runner.py:105} INFO - Job 250: Subtask extract_online_store_data
[2025-02-06T14:16:02.751+0000] {task_command.py:467} INFO - Running <TaskInstance: etl_dag_incremental.extract_online_store_data manual__2025-02-06T14:10:35.575774+00:00 [running]> on host f34e19f1f8c5
[2025-02-06T14:16:02.884+0000] {taskinstance.py:3132} INFO - Exporting env vars: AIRFLOW_CTX_DAG_OWNER='***' AIRFLOW_CTX_DAG_ID='etl_dag_incremental' AIRFLOW_CTX_TASK_ID='extract_online_store_data' AIRFLOW_CTX_EXECUTION_DATE='2025-02-06T14:10:35.575774+00:00' AIRFLOW_CTX_TRY_NUMBER='1' AIRFLOW_CTX_DAG_RUN_ID='manual__2025-02-06T14:10:35.575774+00:00'
[2025-02-06T14:16:02.885+0000] {logging_mixin.py:190} INFO - Task instance is in running state
[2025-02-06T14:16:02.886+0000] {logging_mixin.py:190} INFO -  Previous state of the Task instance: queued
[2025-02-06T14:16:02.886+0000] {logging_mixin.py:190} INFO - Current task name:extract_online_store_data state:running start_date:2025-02-06 14:16:02.644048+00:00
[2025-02-06T14:16:02.886+0000] {logging_mixin.py:190} INFO - Dag name:etl_dag_incremental and current dag run status:running
[2025-02-06T14:16:02.887+0000] {taskinstance.py:731} INFO - ::endgroup::
[2025-02-06T14:16:02.915+0000] {base.py:84} INFO - Retrieving connection 'online_store_conn'
[2025-02-06T14:16:02.919+0000] {sql.py:553} INFO - Running statement: 
            SELECT * FROM online_orders 
            WHERE created_at > '2000-01-01 00:00:00'
            ORDER BY created_at ASC;
        , parameters: None
[2025-02-06T14:16:02.937+0000] {sql.py:562} INFO - Rows affected: 4063
[2025-02-06T14:16:02.966+0000] {etl.py:160} ERROR - Error: name 'convert_decimal' is not defined
[2025-02-06T14:16:02.967+0000] {taskinstance.py:3311} ERROR - Task failed with exception
Traceback (most recent call last):
  File "/home/airflow/.local/lib/python3.12/site-packages/airflow/models/taskinstance.py", line 767, in _execute_task
    result = _execute_callable(context=context, **execute_callable_kwargs)
             ^^^^^^^^^^^^^^^^^^^^^^^^^^^^^^^^^^^^^^^^^^^^^^^^^^^^^^^^^^^^^
  File "/home/airflow/.local/lib/python3.12/site-packages/airflow/models/taskinstance.py", line 733, in _execute_callable
    return ExecutionCallableRunner(
           ^^^^^^^^^^^^^^^^^^^^^^^^
  File "/home/airflow/.local/lib/python3.12/site-packages/airflow/utils/operator_helpers.py", line 252, in run
    return self.func(*args, **kwargs)
           ^^^^^^^^^^^^^^^^^^^^^^^^^^
  File "/home/airflow/.local/lib/python3.12/site-packages/airflow/models/baseoperator.py", line 422, in wrapper
    return func(self, *args, **kwargs)
           ^^^^^^^^^^^^^^^^^^^^^^^^^^^
  File "/home/airflow/.local/lib/python3.12/site-packages/airflow/operators/python.py", line 238, in execute
    return_value = self.execute_callable()
                   ^^^^^^^^^^^^^^^^^^^^^^^
  File "/home/airflow/.local/lib/python3.12/site-packages/airflow/operators/python.py", line 256, in execute_callable
    return runner.run(*self.op_args, **self.op_kwargs)
           ^^^^^^^^^^^^^^^^^^^^^^^^^^^^^^^^^^^^^^^^^^^
  File "/home/airflow/.local/lib/python3.12/site-packages/airflow/utils/operator_helpers.py", line 252, in run
    return self.func(*args, **kwargs)
           ^^^^^^^^^^^^^^^^^^^^^^^^^^
  File "/opt/airflow/dags/etl.py", line 131, in extract_online_store_data
    orders_records = list(map(convert_decimal, orders_records))
                              ^^^^^^^^^^^^^^^
NameError: name 'convert_decimal' is not defined
[2025-02-06T14:16:03.016+0000] {logging_mixin.py:190} INFO - Task instance in failure state
[2025-02-06T14:16:03.016+0000] {logging_mixin.py:190} INFO - Task start:2025-02-06 14:16:02.644048+00:00 end:2025-02-06 14:16:03.015551+00:00 duration:0.371503
[2025-02-06T14:16:03.017+0000] {logging_mixin.py:190} INFO - Task:<Task(PythonOperator): extract_online_store_data> dag:<DAG: etl_dag_incremental> dagrun:<DagRun etl_dag_incremental @ 2025-02-06 14:10:35.575774+00:00: manual__2025-02-06T14:10:35.575774+00:00, state:running, queued_at: 2025-02-06 14:10:35.627538+00:00. externally triggered: True>
[2025-02-06T14:16:03.017+0000] {logging_mixin.py:190} INFO - Failure caused by name 'convert_decimal' is not defined
[2025-02-06T14:16:03.018+0000] {taskinstance.py:1225} INFO - Marking task as UP_FOR_RETRY. dag_id=etl_dag_incremental, task_id=extract_online_store_data, run_id=manual__2025-02-06T14:10:35.575774+00:00, execution_date=20250206T141035, start_date=20250206T141602, end_date=20250206T141603
[2025-02-06T14:16:03.047+0000] {taskinstance.py:340} INFO - ::group::Post task execution logs
[2025-02-06T14:16:03.048+0000] {standard_task_runner.py:124} ERROR - Failed to execute job 250 for task extract_online_store_data (name 'convert_decimal' is not defined; 175)
Traceback (most recent call last):
  File "/home/airflow/.local/lib/python3.12/site-packages/airflow/task/task_runner/standard_task_runner.py", line 117, in _start_by_fork
    ret = args.func(args, dag=self.dag)
          ^^^^^^^^^^^^^^^^^^^^^^^^^^^^^
  File "/home/airflow/.local/lib/python3.12/site-packages/airflow/cli/cli_config.py", line 49, in command
    return func(*args, **kwargs)
           ^^^^^^^^^^^^^^^^^^^^^
  File "/home/airflow/.local/lib/python3.12/site-packages/airflow/utils/cli.py", line 116, in wrapper
    return f(*args, **kwargs)
           ^^^^^^^^^^^^^^^^^^
  File "/home/airflow/.local/lib/python3.12/site-packages/airflow/cli/commands/task_command.py", line 483, in task_run
    task_return_code = _run_task_by_selected_method(args, _dag, ti)
                       ^^^^^^^^^^^^^^^^^^^^^^^^^^^^^^^^^^^^^^^^^^^^
  File "/home/airflow/.local/lib/python3.12/site-packages/airflow/cli/commands/task_command.py", line 256, in _run_task_by_selected_method
    return _run_raw_task(args, ti)
           ^^^^^^^^^^^^^^^^^^^^^^^
  File "/home/airflow/.local/lib/python3.12/site-packages/airflow/cli/commands/task_command.py", line 341, in _run_raw_task
    return ti._run_raw_task(
           ^^^^^^^^^^^^^^^^^
  File "/home/airflow/.local/lib/python3.12/site-packages/airflow/utils/session.py", line 97, in wrapper
    return func(*args, session=session, **kwargs)
           ^^^^^^^^^^^^^^^^^^^^^^^^^^^^^^^^^^^^^^
  File "/home/airflow/.local/lib/python3.12/site-packages/airflow/models/taskinstance.py", line 3005, in _run_raw_task
    return _run_raw_task(
           ^^^^^^^^^^^^^^
  File "/home/airflow/.local/lib/python3.12/site-packages/airflow/models/taskinstance.py", line 273, in _run_raw_task
    TaskInstance._execute_task_with_callbacks(
  File "/home/airflow/.local/lib/python3.12/site-packages/airflow/models/taskinstance.py", line 3159, in _execute_task_with_callbacks
    result = self._execute_task(context, task_orig)
             ^^^^^^^^^^^^^^^^^^^^^^^^^^^^^^^^^^^^^^
  File "/home/airflow/.local/lib/python3.12/site-packages/airflow/models/taskinstance.py", line 3183, in _execute_task
    return _execute_task(self, context, task_orig)
           ^^^^^^^^^^^^^^^^^^^^^^^^^^^^^^^^^^^^^^^
  File "/home/airflow/.local/lib/python3.12/site-packages/airflow/models/taskinstance.py", line 767, in _execute_task
    result = _execute_callable(context=context, **execute_callable_kwargs)
             ^^^^^^^^^^^^^^^^^^^^^^^^^^^^^^^^^^^^^^^^^^^^^^^^^^^^^^^^^^^^^
  File "/home/airflow/.local/lib/python3.12/site-packages/airflow/models/taskinstance.py", line 733, in _execute_callable
    return ExecutionCallableRunner(
           ^^^^^^^^^^^^^^^^^^^^^^^^
  File "/home/airflow/.local/lib/python3.12/site-packages/airflow/utils/operator_helpers.py", line 252, in run
    return self.func(*args, **kwargs)
           ^^^^^^^^^^^^^^^^^^^^^^^^^^
  File "/home/airflow/.local/lib/python3.12/site-packages/airflow/models/baseoperator.py", line 422, in wrapper
    return func(self, *args, **kwargs)
           ^^^^^^^^^^^^^^^^^^^^^^^^^^^
  File "/home/airflow/.local/lib/python3.12/site-packages/airflow/operators/python.py", line 238, in execute
    return_value = self.execute_callable()
                   ^^^^^^^^^^^^^^^^^^^^^^^
  File "/home/airflow/.local/lib/python3.12/site-packages/airflow/operators/python.py", line 256, in execute_callable
    return runner.run(*self.op_args, **self.op_kwargs)
           ^^^^^^^^^^^^^^^^^^^^^^^^^^^^^^^^^^^^^^^^^^^
  File "/home/airflow/.local/lib/python3.12/site-packages/airflow/utils/operator_helpers.py", line 252, in run
    return self.func(*args, **kwargs)
           ^^^^^^^^^^^^^^^^^^^^^^^^^^
  File "/opt/airflow/dags/etl.py", line 131, in extract_online_store_data
    orders_records = list(map(convert_decimal, orders_records))
                              ^^^^^^^^^^^^^^^
NameError: name 'convert_decimal' is not defined
[2025-02-06T14:16:03.104+0000] {local_task_job_runner.py:266} INFO - Task exited with return code 1
[2025-02-06T14:16:03.119+0000] {local_task_job_runner.py:245} INFO - ::endgroup::
